  <entry id="CVE-2009-5010">
    <vuln:vulnerable-configuration id="http://nvd.nist.gov/">
      <cpe-lang:logical-test negate="false" operator="OR">
        <cpe-lang:fact-ref name="cpe:/a:g.rodola:pyftpdlib:0.5.0"/>
        <cpe-lang:fact-ref name="cpe:/a:g.rodola:pyftpdlib:0.4.0"/>
        <cpe-lang:fact-ref name="cpe:/a:g.rodola:pyftpdlib:0.3.0"/>
        <cpe-lang:fact-ref name="cpe:/a:g.rodola:pyftpdlib:0.2.0"/>
        <cpe-lang:fact-ref name="cpe:/a:g.rodola:pyftpdlib:0.1.1"/>
        <cpe-lang:fact-ref name="cpe:/a:g.rodola:pyftpdlib:0.1"/>
      </cpe-lang:logical-test>
    </vuln:vulnerable-configuration>
    <vuln:vulnerable-software-list>
      <vuln:product>cpe:/a:g.rodola:pyftpdlib:0.1</vuln:product>
      <vuln:product>cpe:/a:g.rodola:pyftpdlib:0.5.0</vuln:product>
      <vuln:product>cpe:/a:g.rodola:pyftpdlib:0.1.1</vuln:product>
      <vuln:product>cpe:/a:g.rodola:pyftpdlib:0.3.0</vuln:product>
      <vuln:product>cpe:/a:g.rodola:pyftpdlib:0.4.0</vuln:product>
      <vuln:product>cpe:/a:g.rodola:pyftpdlib:0.2.0</vuln:product>
    </vuln:vulnerable-software-list>
    <vuln:cve-id>CVE-2009-5010</vuln:cve-id>
    <vuln:published-datetime>2010-10-19T16:00:02.957-04:00</vuln:published-datetime>
    <vuln:last-modified-datetime>2010-10-20T00:00:00.000-04:00</vuln:last-modified-datetime>
    <vuln:cvss>
      <cvss:base_metrics>
        <cvss:score>4.3</cvss:score>
        <cvss:access-vector>NETWORK</cvss:access-vector>
        <cvss:access-complexity>MEDIUM</cvss:access-complexity>
        <cvss:authentication>NONE</cvss:authentication>
        <cvss:confidentiality-impact>NONE</cvss:confidentiality-impact>
        <cvss:integrity-impact>NONE</cvss:integrity-impact>
        <cvss:availability-impact>PARTIAL</cvss:availability-impact>
        <cvss:source>http://nvd.nist.gov</cvss:source>
        <cvss:generated-on-datetime>2010-10-20T13:47:00.000-04:00</cvss:generated-on-datetime>
      </cvss:base_metrics>
    </vuln:cvss>
    <vuln:cwe id="CWE-362"/>
    <vuln:references xml:lang="en" reference_type="PATCH">
      <vuln:source>MISC</vuln:source>
      <vuln:reference href="http://bugs.python.org/issue6706" xml:lang="en">http://bugs.python.org/issue6706</vuln:reference>
    </vuln:references>
    <vuln:references xml:lang="en" reference_type="UNKNOWN">
      <vuln:source>MISC</vuln:source>
      <vuln:reference href="https://bugs.launchpad.net/zodb/+bug/135108" xml:lang="en">https://bugs.launchpad.net/zodb/+bug/135108</vuln:reference>
    </vuln:references>
    <vuln:references xml:lang="en" reference_type="UNKNOWN">
      <vuln:source>MLIST</vuln:source>
      <vuln:reference href="http://www.openwall.com/lists/oss-security/2010/09/24/3" xml:lang="en">[oss-security] 20100924 Re: CVE Request -- Python -- accept() implementation in async core is broken => more subcases</vuln:reference>
    </vuln:references>
    <vuln:references xml:lang="en" reference_type="UNKNOWN">
      <vuln:source>MLIST</vuln:source>
      <vuln:reference href="http://www.openwall.com/lists/oss-security/2010/09/22/3" xml:lang="en">[oss-security] 20100922 Re: CVE Request -- Python -- accept() implementation in async core is broken => more subcases</vuln:reference>
    </vuln:references>
    <vuln:references xml:lang="en" reference_type="UNKNOWN">
      <vuln:source>MLIST</vuln:source>
      <vuln:reference href="http://www.openwall.com/lists/oss-security/2010/09/11/2" xml:lang="en">[oss-security] 20100910 Re: CVE Request -- Python -- accept() implementation in async core is broken => more subcases</vuln:reference>
    </vuln:references>
    <vuln:references xml:lang="en" reference_type="UNKNOWN">
      <vuln:source>MLIST</vuln:source>
      <vuln:reference href="http://www.openwall.com/lists/oss-security/2010/09/09/6" xml:lang="en">[oss-security] 20100909 CVE Request -- Python -- accept() implementation in async core is broken => more subcases</vuln:reference>
    </vuln:references>
    <vuln:references xml:lang="en" reference_type="UNKNOWN">
      <vuln:source>CONFIRM</vuln:source>
      <vuln:reference href="http://code.google.com/p/pyftpdlib/source/diff?spec=svn439&amp;r=439&amp;format=side&amp;path=/trunk/pyftpdlib/ftpserver.py" xml:lang="en">http://code.google.com/p/pyftpdlib/source/diff?spec=svn439&amp;r=439&amp;format=side&amp;path=/trunk/pyftpdlib/ftpserver.py</vuln:reference>
    </vuln:references>
    <vuln:references xml:lang="en" reference_type="UNKNOWN">
      <vuln:source>CONFIRM</vuln:source>
      <vuln:reference href="http://code.google.com/p/pyftpdlib/source/detail?r=439" xml:lang="en">http://code.google.com/p/pyftpdlib/source/detail?r=439</vuln:reference>
    </vuln:references>
    <vuln:references xml:lang="en" reference_type="UNKNOWN">
      <vuln:source>CONFIRM</vuln:source>
      <vuln:reference href="http://code.google.com/p/pyftpdlib/source/browse/trunk/HISTORY" xml:lang="en">http://code.google.com/p/pyftpdlib/source/browse/trunk/HISTORY</vuln:reference>
    </vuln:references>
    <vuln:references xml:lang="en" reference_type="UNKNOWN">
      <vuln:source>CONFIRM</vuln:source>
      <vuln:reference href="http://code.google.com/p/pyftpdlib/issues/detail?id=91" xml:lang="en">http://code.google.com/p/pyftpdlib/issues/detail?id=91</vuln:reference>
    </vuln:references>
    <vuln:summary>Race condition in the FTPHandler class in ftpserver.py in pyftpdlib before 0.5.1 allows remote attackers to cause a denial of service (daemon outage) by establishing and then immediately closing a TCP connection, leading to the accept function having an unexpected return value of None, a different vulnerability than CVE-2010-3494.</vuln:summary>
  </entry>
