  <entry id="CVE-2006-1542">
    <vuln:vulnerable-configuration id="http://nvd.nist.gov/">
      <cpe-lang:logical-test negate="false" operator="OR">
        <cpe-lang:fact-ref name="cpe:/a:python_software_foundation:python:2.2"/>
        <cpe-lang:fact-ref name="cpe:/a:python_software_foundation:python:2.2.1"/>
        <cpe-lang:fact-ref name="cpe:/a:python_software_foundation:python:2.3"/>
        <cpe-lang:fact-ref name="cpe:/a:python_software_foundation:python:2.3.1"/>
        <cpe-lang:fact-ref name="cpe:/a:python_software_foundation:python:2.3.2"/>
        <cpe-lang:fact-ref name="cpe:/a:python_software_foundation:python:2.3.3"/>
        <cpe-lang:fact-ref name="cpe:/a:python_software_foundation:python:2.3.4"/>
        <cpe-lang:fact-ref name="cpe:/a:python_software_foundation:python:2.4"/>
        <cpe-lang:fact-ref name="cpe:/a:python_software_foundation:python:2.4.2"/>
      </cpe-lang:logical-test>
    </vuln:vulnerable-configuration>
    <vuln:vulnerable-software-list>
      <vuln:product>cpe:/a:python_software_foundation:python:2.3.3</vuln:product>
      <vuln:product>cpe:/a:python_software_foundation:python:2.3.4</vuln:product>
      <vuln:product>cpe:/a:python_software_foundation:python:2.4</vuln:product>
      <vuln:product>cpe:/a:python_software_foundation:python:2.2.1</vuln:product>
      <vuln:product>cpe:/a:python_software_foundation:python:2.3.2</vuln:product>
      <vuln:product>cpe:/a:python_software_foundation:python:2.3.1</vuln:product>
      <vuln:product>cpe:/a:python_software_foundation:python:2.4.2</vuln:product>
      <vuln:product>cpe:/a:python_software_foundation:python:2.2</vuln:product>
      <vuln:product>cpe:/a:python_software_foundation:python:2.3</vuln:product>
    </vuln:vulnerable-software-list>
    <vuln:cve-id>CVE-2006-1542</vuln:cve-id>
    <vuln:discovered-datetime>2006-03-18T00:00:00.000-05:00</vuln:discovered-datetime>
    <vuln:published-datetime>2006-03-30T06:02:00.000-05:00</vuln:published-datetime>
    <vuln:last-modified-datetime>2009-01-23T00:53:24.343-05:00</vuln:last-modified-datetime>
    <vuln:cvss>
      <cvss:base_metrics upgraded-from-version="1.0">
        <cvss:score>3.7</cvss:score>
        <cvss:access-vector>LOCAL</cvss:access-vector>
        <cvss:access-complexity>HIGH</cvss:access-complexity>
        <cvss:authentication>NONE</cvss:authentication>
        <cvss:confidentiality-impact>PARTIAL</cvss:confidentiality-impact>
        <cvss:integrity-impact>PARTIAL</cvss:integrity-impact>
        <cvss:availability-impact>PARTIAL</cvss:availability-impact>
        <cvss:source>http://nvd.nist.gov</cvss:source>
        <cvss:generated-on-datetime>2006-03-31T11:49:00.000-05:00</cvss:generated-on-datetime>
      </cvss:base_metrics>
    </vuln:cvss>
    <vuln:security-protection>ALLOWS_OTHER_ACCESS</vuln:security-protection>
    <vuln:references xml:lang="en" reference_type="UNKNOWN">
      <vuln:source>REDHAT</vuln:source>
      <vuln:reference href="http://www.redhat.com/support/errata/RHSA-2008-0629.html" xml:lang="en">RHSA-2008:0629</vuln:reference>
    </vuln:references>
    <vuln:references xml:lang="en" reference_type="UNKNOWN">
      <vuln:source>MISC</vuln:source>
      <vuln:reference href="http://www.gotfault.net/research/exploit/gexp-python.py" xml:lang="en">http://www.gotfault.net/research/exploit/gexp-python.py</vuln:reference>
    </vuln:references>
    <vuln:references xml:lang="en" reference_type="UNKNOWN">
      <vuln:source>SECUNIA</vuln:source>
      <vuln:reference href="http://secunia.com/advisories/31492" xml:lang="en">31492</vuln:reference>
    </vuln:references>
    <vuln:references xml:lang="en" reference_type="UNKNOWN">
      <vuln:source>MILW0RM</vuln:source>
      <vuln:reference href="http://milw0rm.com/exploits/1591" xml:lang="en">1591</vuln:reference>
    </vuln:references>
    <vuln:summary>Stack-based buffer overflow in Python 2.4.2 and earlier, running on Linux 2.6.12.5 under gcc 4.0.3 with libc 2.3.5, allows local users to cause a "stack overflow," and possibly gain privileges, by running a script from a current working directory that has a long name, related to the realpath function.  NOTE: this might not be a vulnerability. However, the fact that it appears in a programming language interpreter could mean that some applications are affected, although attack scenarios might be limited because the attacker might already need to cross privilege boundaries to cause an exploitable program to be placed in a directory with a long name; or, depending on the method that Python uses to determine the current working directory, setuid applications might be affected.</vuln:summary>
  </entry>
